<?xml version="1.0"?>
<robot xmlns:xacro="http://ros.org/wiki/xacro">	

    <xacro:property name="pi" value="3.141592654" />

    <xacro:macro name="robotis_humanoid_head" params="parent">

	<!-- head yaw joint -->
        <joint name="head_y" type="revolute">
          <axis xyz="0 0 1" />		
          <origin xyz="0.0 0.0 0.229" rpy="0 0 0"/>
          <parent link="${parent}"/>
          <child link="head_y_link"/>
          <!--limit velocity="6.5" effort="1000" lower="${-pi*0.5}" upper="${pi*0.5}" />
          <dynamics damping="0.1" friction="0.1" /-->
	  <xacro:joint_small_servo_limits_macro lower="${-pi*0.5}" upper="${pi*0.5}" />
        </joint> 
        <xacro:effort_transmission name="head_y" servo="H42-20-S300" />

	<!-- head yaw link -->
        <link name="head_y_link">
    	  <collision>
      	    <origin xyz="0 0 0" rpy="0 0 0"/>
      	    <geometry>
              <box size="0.01 0.01 0.01" />
      	    </geometry>
    	  </collision>

   	  <visual>
      	    <origin xyz="0 0 0" rpy="0 0 0"/>
      	    <geometry>
              <mesh filename="package://robotis_humanoid_description/meshes/robotis_head_y_link.stl" scale="0.001 0.001 0.001"/>
      	    </geometry>
      	    <material name="grey"/>
    	  </visual>

          <xacro:inertial_cuboid_macro mass="0.2" x_length="0.040" y_length="0.100" z_length="0.050" />
        </link>

	<!-- head pitch joint -->
        <joint name="head_p" type="revolute">
          <axis xyz="0 1 0" />		
          <origin xyz="0.0 -0.045 0.039" rpy="0 0 0"/>
          <parent link="head_y_link"/>
          <child link="head_p_link"/>
          <!--limit velocity="6.5" effort="1000" lower="${-pi*0.5}" upper="${pi*0.5}" />
          <dynamics damping="0.1" friction="0.1" /-->
	  <xacro:joint_small_servo_limits_macro lower="${-pi*0.5}" upper="${pi*0.5}" />
        </joint> 
        <xacro:effort_transmission name="head_p" servo="H42-20-S300" />

	<!-- head pitch link -->
        <link name="head_p_link">
    	  <collision>
      	    <origin xyz="0 0 0" rpy="0 0 0"/>
      	    <geometry>
              <box size="0.01 0.01 0.01" />
      	    </geometry>
    	  </collision>

   	  <visual>
      	    <origin xyz="0 0 0" rpy="0 0 0"/>
      	    <geometry>
              <mesh filename="package://robotis_humanoid_description/meshes/robotis_head_p_link.stl" scale="0.001 0.001 0.001"/>
      	    </geometry>
      	    <material name="grey"/>
    	  </visual>

          <xacro:inertial_cuboid_with_pose_macro mass="1.0" x_length="0.110" y_length="0.130" z_length="0.150">
	    <origin xyz="0 0.050 0.050" rpy="0 0 0"/>
	  </xacro:inertial_cuboid_with_pose_macro>
        </link>

	<!-- camera joint -->
        <joint name="cam" type="fixed">
          <origin xyz="0.0682 0.045 0.056" rpy="0 ${pi*0.5} 0"/>
          <parent link="head_p_link"/>
          <child link="cam_link"/>
        </joint> 

	<!-- camera link -->
        <link name="cam_link">
        </link>

	<!-- lidar joint -->
        <joint name="lidar_fixed" type="fixed">
          <origin xyz="0.0 0.045 0.10675" rpy="0 0 0"/>
          <parent link="head_p_link"/>
          <child link="lidar_link"/>
        </joint> 

	<!-- lidar link -->
        <link name="lidar_link">
        </link>

	<!-- realsense joint -->
        <joint name="realsense_fixed" type="fixed">
          <origin xyz="0.0689 0.045 0.017" rpy="0 0 0"/>
          <parent link="head_p_link"/>
          <child link="realsense_link"/>
        </joint> 

	<!-- realsense link -->
        <link name="realsense_link">
        </link>

	<!-- realsense joint rotation -->
        <joint name="realsense_fixed_rotation" type="fixed">
          <origin xyz="0.0 0.0 0.0" rpy="${-pi*0.5} 0 ${-pi*0.5}"/>
          <parent link="realsense_link"/>
          <child link="realsense_frame"/>
        </joint>

	<!-- realsense frame -->
        <link name="realsense_frame">
        </link>

    </xacro:macro>


</robot>
