<?xml version="1.0"?>
<robot xmlns:xacro="http://ros.org/wiki/xacro">	

    <xacro:property name="pi" value="3.141592654" />

    <xacro:macro name="robotis_humanoid_hand" params="prefix reflect">


	<!-- robotis gripper -->

        <link name="${prefix}_arm_wr_p_link">
    	  <collision>
      	    <origin xyz="0 0 0" rpy="0 0 0"/>
      	    <geometry>
              <box size="0.01 0.01 0.01" />
      	    </geometry>
    	  </collision>

   	  <visual>
      	    <origin xyz="0 0 0" rpy="0 0 0"/>
      	    <geometry>
              <mesh filename="package://robotis_humanoid_description/meshes/robotis_${prefix}_arm_wr_p_link.stl" scale="0.001 0.001 0.001"/>
      	    </geometry>
      	    <material name="grey"/>
    	  </visual>

          <inertial>
      	    <origin xyz="0.065 ${reflect*0.045} 0.000" rpy="0 0 0"/>
      	    <mass value="0.565"/>
            <inertia ixx="0.00047" ixy="${reflect*-0.00001}" ixz="0.0" iyy="0.00042" iyz="0.0" izz="0.00058" />
    	  </inertial>
        </link>



        <joint name="${prefix}_arm_grip" type="revolute">
          <axis xyz="0 0 1" />		
          <origin xyz="0.0877 ${reflect*0.0583} 0.0" rpy="0 0 0"/>
          <parent link="${prefix}_arm_wr_p_link"/>
          <child link="${prefix}_arm_grip_link"/>
          <limit velocity="6.5" effort="1000" lower="${-pi*0.45}" upper="${pi*0.45}" />
          <dynamics damping="0.1" friction="0.1" />
        </joint> 
        <xacro:position_transmission name="${prefix}_arm_grip" servo="H42-20-S300" />

        <link name="${prefix}_arm_grip_link">
    	  <collision>
      	    <origin xyz="0 0 0" rpy="0 0 0"/>
      	    <geometry>
              <box size="0.01 0.01 0.01" />
      	    </geometry>
    	  </collision>

   	  <visual>
      	    <origin xyz="0 0 0" rpy="0 0 0"/>
      	    <geometry>
              <mesh filename="package://robotis_humanoid_description/meshes/robotis_${prefix}_arm_grip_link.stl" scale="0.001 0.001 0.001"/>
      	    </geometry>
      	    <material name="grey"/>
    	  </visual>

          <inertial>
      	    <origin xyz="0.031 ${reflect*0.014} 0.000" rpy="0 0 0"/>
      	    <mass value="0.013"/>
            <inertia ixx="0.0" ixy="0.0" ixz="0.0" iyy="0.00001" iyz="0.0" izz="0.00001" />
    	  </inertial>
        </link>

        <joint name="${prefix}_arm_grip_1" type="revolute">
          <axis xyz="0 0 1" />		
          <origin xyz="0.0877 ${reflect*0.0317} 0.0" rpy="0 0 0"/>
          <parent link="${prefix}_arm_wr_p_link"/>
          <child link="${prefix}_arm_grip_1_link"/>
          <limit velocity="6.5" effort="1000" lower="${-pi*0.45}" upper="${pi*0.45}" />
          <dynamics damping="0.1" friction="0.1" />
        </joint> 
        <xacro:position_transmission name="${prefix}_arm_grip_1" servo="H42-20-S300" />

        <link name="${prefix}_arm_grip_1_link">
    	  <collision>
      	    <origin xyz="0 0 0" rpy="0 0 0"/>
      	    <geometry>
              <box size="0.01 0.01 0.01" />
      	    </geometry>
    	  </collision>

   	  <visual>
      	    <origin xyz="0 0 0" rpy="0 0 0"/>
      	    <geometry>
              <mesh filename="package://robotis_humanoid_description/meshes/robotis_${prefix}_arm_grip_1_link.stl" scale="0.001 0.001 0.001"/>
      	    </geometry>
      	    <material name="grey"/>
    	  </visual>

          <inertial>
      	    <origin xyz="0.031 ${reflect*-0.014} 0.000" rpy="0 0 0"/>
      	    <mass value="0.013"/>
            <inertia ixx="0.0" ixy="0.0" ixz="0.0" iyy="0.00001" iyz="0.0" izz="0.00001" /> 
    	  </inertial>
        </link>

        <joint name="${prefix}_arm_end" type="fixed">
          <origin xyz="0.145 ${reflect*0.045} 0" rpy="0 0 0"/>
          <parent link="${prefix}_arm_wr_p_link"/>
          <child link="${prefix}_arm_end_link"/>
        </joint> 

        <link name="${prefix}_arm_end_link">
    	  <collision>
      	    <origin xyz="0 0 0" rpy="0 0 0"/>
      	    <geometry>
              <box size="0.01 0.01 0.01" />
      	    </geometry>
    	  </collision>

   	  <visual>
      	    <origin xyz="0 0 0" rpy="0 0 0"/>
      	    <geometry>
              <box size="0.01 0.01 0.01" />
      	    </geometry>
      	    <material name="red"/>
    	  </visual>

          <inertial>
      	    <origin xyz="0.0 0.0 0.0" rpy="0 0 0"/>
      	    <mass value="0.001"/>
      	    <inertia ixx="0.00001" ixy="0.0" ixz="0.0" iyy="0.00001" iyz="0.0" izz="0.00001" />
    	  </inertial>
        </link>

    </xacro:macro>

</robot>
