<?xml version="1.0"?>
<robot xmlns:xacro="http://ros.org/wiki/xacro">	

    <xacro:property name="pi" value="3.141592654" />

    <xacro:macro name="robotis_humanoid_torso">

      <!-- pelvis_link -->
      <link name="pelvis_link">
        <collision>
          <origin xyz="0 0 0" rpy="0 0 0"/>
          <geometry>
            <box size="0.01 0.01 0.01" />
          </geometry>
        </collision>

        <visual>
          <origin xyz="0 0 0" rpy="0 0 0"/>
          <geometry>
            <mesh filename="package://robotis_humanoid_description/meshes/robotis_pelvis_link.stl" scale="0.001 0.001 0.001"/>
          </geometry>
          <material name="grey"/>
        </visual>

        <inertial>
          <origin xyz="-0.011 0.000 0.058" rpy="0 0 0"/>
          <mass value="6.869"/>
          <inertia ixx="0.03603" ixy="0.0" ixz="0.00016" iyy="0.02210" iyz="0.0" izz="0.03830" />
        </inertial>
      </link>

      <!-- torso yaw joint -->
      <joint name="torso_y" type="revolute">
        <parent link="pelvis_link"/>
        <child link="chest_link"/>
        <origin xyz="0 0 0.1705" rpy="0 0 0"/>
        <axis xyz="0 0 1"/>
        <!--limit velocity="6.5" effort="1000" lower="${-pi*0.6}" upper="${pi*0.6}" />
        <dynamics damping="0.1" friction="0.1" /-->
        <xacro:joint_medium_servo_limits_macro lower="${-pi*0.6}" upper="${pi*0.6}" />
      </joint>
      <xacro:position_transmission name="torso_y" servo="H54-100-S500" />
  
      <!-- chest_link -->
      <link name="chest_link">
        <collision>
          <origin xyz="0 0 0" rpy="0 0 0"/>
          <geometry>
            <box size="0.01 0.01 0.01" />
          </geometry>
        </collision>

        <visual>
          <origin xyz="0 0 0" rpy="0 0 0"/>
          <geometry>
            <mesh filename="package://robotis_humanoid_description/meshes/robotis_chest_link.stl" scale="0.001 0.001 0.001"/>
          </geometry>
          <material name="grey"/>
        </visual>

        <inertial>
          <origin xyz="-0.007 0.000 0.109" rpy="0 0 0"/>
          <mass value="5.383"/>
          <inertia ixx="0.04710" ixy="0.0" ixz="0.04710" iyy="0.02554" iyz="0.0" izz="0.03094" /> 
        </inertial>
      </link>

      <!-- imu joint -->
      <joint name="imu_fixed" type="fixed">
        <parent link="pelvis_link"/>
        <child link="imu_link"/>
        <origin xyz="0.03 0 0.0" rpy="0 0 ${pi}"/>
      </joint>

      <link name="imu_link">
      </link>

    </xacro:macro>


</robot>
